Workbook

Sheet Summary
A1: Perez Household - 2026-09 Expenses
A2: Cash (checking) and card spending by category, from the Perez Household Ledger.
A4: Group | B4: Category | C4: Cash | D4: Card | E4: Total
A5: Monthly Bills | B5: Car insurance | C5: =SUMIFS('Line Items'!$F$2:$F$194,'Line Items'!$D$2:$D$194,$A5,'Line Items'!$E$2:$E$194,$B5,'Line Items'!$C$2:$C$194,"Checking") -> 278.91 | D5: =SUMIFS('Line Items'!$F$2:$F$194,'Line Items'!$D$2:$D$194,$A5,'Line Items'!$E$2:$E$194,$B5,'Line Items'!$C$2:$C$194,"<>Checking") -> 310.89 | E5: =C5+D5 -> 589.8
A6: Monthly Bills | B6: Verizon | C6: =SUMIFS('Line Items'!$F$2:$F$194,'Line Items'!$D$2:$D$194,$A6,'Line Items'!$E$2:$E$194,$B6,'Line Items'!$C$2:$C$194,"Checking") -> 401.75 | D6: =SUMIFS('Line Items'!$F$2:$F$194,'Line Items'!$D$2:$D$194,$A6,'Line Items'!$E$2:$E$194,$B6,'Line Items'!$C$2:$C$194,"<>Checking") -> 0 | E6: =C6+D6 -> 401.75
A7: Monthly Bills | B7: NV Energy | C7: =SUMIFS('Line Items'!$F$2:$F$194,'Line Items'!$D$2:$D$194,$A7,'Line Items'!$E$2:$E$194,$B7,'Line Items'!$C$2:$C$194,"Checking") -> 289.55 | D7: =SUMIFS('Line Items'!$F$2:$F$194,'Line Items'!$D$2:$D$194,$A7,'Line Items'!$E$2:$E$194,$B7,'Line Items'!$C$2:$C$194,"<>Checking") -> 0 | E7: =C7+D7 -> 289.55
A8: Monthly Bills | B8: National Life Ins | C8: =SUMIFS('Line Items'!$F$2:$F$194,'Line Items'!$D$2:$D$194,$A8,'Line Items'!$E$2:$E$194,$B8,'Line Items'!$C$2:$C$194,"Checking") -> 205.62 | D8: =SUMIFS('Line Items'!$F$2:$F$194,'Line Items'!$D$2:$D$194,$A8,'Line Items'!$E$2:$E$194,$B8,'Line Items'!$C$2:$C$194,"<>Checking") -> 0 | E8: =C8+D8 -> 205.62
A9: Monthly Bills | B9: Atty Chua | C9: =SUMIFS('Line Items'!$F$2:$F$194,'Line Items'!$D$2:$D$194,$A9,'Line Items'!$E$2:$E$194,$B9,'Line Items'!$C$2:$C$194,"Checking") -> 200 | D9: =SUMIFS('Line Items'!$F$2:$F$194,'Line Items'!$D$2:$D$194,$A9,'Line Items'!$E$2:$E$194,$B9,'Line Items'!$C$2:$C$194,"<>Checking") -> 0 | E9: =C9+D9 -> 200
A10: Monthly Bills | B10: Cox | C10: =SUMIFS('Line Items'!$F$2:$F$194,'Line Items'!$D$2:$D$194,$A10,'Line Items'!$E$2:$E$194,$B10,'Line Items'!$C$2:$C$194,"Checking") -> 130 | D10: =SUMIFS('Line Items'!$F$2:$F$194,'Line Items'!$D$2:$D$194,$A10,'Line Items'!$E$2:$E$194,$B10,'Line Items'!$C$2:$C$194,"<>Checking") -> 0 | E10: =C10+D10 -> 130
A11: Monthly Bills | B11: PGE | C11: =SUMIFS('Line Items'!$F$2:$F$194,'Line Items'!$D$2:$D$194,$A11,'Line Items'!$E$2:$E$194,$B11,'Line Items'!$C$2:$C$194,"Checking") -> 93.31 | D11: =SUMIFS('Line Items'!$F$2:$F$194,'Line Items'!$D$2:$D$194,$A11,'Line Items'!$E$2:$E$194,$B11,'Line Items'!$C$2:$C$194,"<>Checking") -> 0 | E11: =C11+D11 -> 93.31
A12: Monthly Bills | B12: Prulife | C12: =SUMIFS('Line Items'!$F$2:$F$194,'Line Items'!$D$2:$D$194,$A12,'Line Items'!$E$2:$E$194,$B12,'Line Items'!$C$2:$C$194,"Checking") -> 59.67 | D12: =SUMIFS('Line Items'!$F$2:$F$194,'Line Items'!$D$2:$D$194,$A12,'Line Items'!$E$2:$E$194,$B12,'Line Items'!$C$2:$C$194,"<>Checking") -> 0 | E12: =C12+D12 -> 59.67
A13: Monthly Bills | B13: Cal Water | C13: =SUMIFS('Line Items'!$F$2:$F$194,'Line Items'!$D$2:$D$194,$A13,'Line Items'!$E$2:$E$194,$B13,'Line Items'!$C$2:$C$194,"Checking") -> 49.72 | D13: =SUMIFS('Line Items'!$F$2:$F$194,'Line Items'!$D$2:$D$194,$A13,'Line Items'!$E$2:$E$194,$B13,'Line Items'!$C$2:$C$194,"<>Checking") -> 0 | E13: =C13+D13 -> 49.72
A14: Monthly Bills | B14: Republic Services | C14: =SUMIFS('Line Items'!$F$2:$F$194,'Line Items'!$D$2:$D$194,$A14,'Line Items'!$E$2:$E$194,$B14,'Line Items'!$C$2:$C$194,"Checking") -> 48.96 | D14: =SUMIFS('Line Items'!$F$2:$F$194,'Line Items'!$D$2:$D$194,$A14,'Line Items'!$E$2:$E$194,$B14,'Line Items'!$C$2:$C$194,"<>Checking") -> 0 | E14: =C14+D14 -> 48.96
A15: Monthly Bills | B15: Netflix | C15: =SUMIFS('Line Items'!$F$2:$F$194,'Line Items'!$D$2:$D$194,$A15,'Line Items'!$E$2:$E$194,$B15,'Line Items'!$C$2:$C$194,"Checking") -> 29.98 | D15: =SUMIFS('Line Items'!$F$2:$F$194,'Line Items'!$D$2:$D$194,$A15,'Line Items'!$E$2:$E$194,$B15,'Line Items'!$C$2:$C$194,"<>Checking") -> 0 | E15: =C15+D15 -> 29.98
A16: Monthly Bills | B16: Amazon Prime | C16: =SUMIFS('Line Items'!$F$2:$F$194,'Line Items'!$D$2:$D$194,$A16,'Line Items'!$E$2:$E$194,$B16,'Line Items'!$C$2:$C$194,"Checking") -> 14.99 | D16: =SUMIFS('Line Items'!$F$2:$F$194,'Line Items'!$D$2:$D$194,$A16,'Line Items'!$E$2:$E$194,$B16,'Line Items'!$C$2:$C$194,"<>Checking") -> 0 | E16: =C16+D16 -> 14.99
... A19: Monthly Bills | B19: Life 360 | C19: =SUMIFS('Line Items'!$F$2:$F$194,'Line Items'!$D$2:$D$194,$A19,'Line Items'!$E$2:$E$194,$B19,'Line Items'!$C$2:$C$194,"Checking") -> 13.49 | D19: =SUMIFS('Line Items'!$F$2:$F$194,'Line Items'!$D$2:$D$194,$A19,'Line Items'!$E$2:$E$194,$B19,'Line Items'!$C$2:$C$194,"<>Checking") -> 0 | E19: =C19+D19 -> 13.49
A20: Total Monthly Bills | C20: =SUM(C5:C19) -> 1844.33 | D20: =SUM(D5:D19) -> 310.89 | E20: =SUM(E5:E19) -> 2155.22
A22: Expenses | B22: Others | C22: =SUMIFS('Line Items'!$F$2:$F$194,'Line Items'!$D$2:$D$194,$A22,'Line Items'!$E$2:$E$194,$B22,'Line Items'!$C$2:$C$194,"Checking") -> 2890.9 | D22: =SUMIFS('Line Items'!$F$2:$F$194,'Line Items'!$D$2:$D$194,$A22,'Line Items'!$E$2:$E$194,$B22,'Line Items'!$C$2:$C$194,"<>Checking") -> 30 | E22: =C22+D22 -> 2920.9
A23: Expenses | B23: Food - Eat Out | C23: =SUMIFS('Line Items'!$F$2:$F$194,'Line Items'!$D$2:$D$194,$A23,'Line Items'!$E$2:$E$194,$B23,'Line Items'!$C$2:$C$194,"Checking") -> 1280.67 | D23: =SUMIFS('Line Items'!$F$2:$F$194,'Line Items'!$D$2:$D$194,$A23,'Line Items'!$E$2:$E$194,$B23,'Line Items'!$C$2:$C$194,"<>Checking") -> 0 | E23: =C23+D23 -> 1280.67
A24: Expenses | B24: Groceries - Walmart | C24: =SUMIFS('Line Items'!$F$2:$F$194,'Line Items'!$D$2:$D$194,$A24,'Line Items'!$E$2:$E$194,$B24,'Line Items'!$C$2:$C$194,"Checking") -> 762.18 | D24: =SUMIFS('Line Items'!$F$2:$F$194,'Line Items'!$D$2:$D$194,$A24,'Line Items'!$E$2:$E$194,$B24,'Line Items'!$C$2:$C$194,"<>Checking") -> 0 | E24: =C24+D24 -> 762.18
A25: Expenses | B25: Shop - Amazon | C25: =SUMIFS('Line Items'!$F$2:$F$194,'Line Items'!$D$2:$D$194,$A25,'Line Items'!$E$2:$E$194,$B25,'Line Items'!$C$2:$C$194,"Checking") -> 741.55 | D25: =SUMIFS('Line Items'!$F$2:$F$194,'Line Items'!$D$2:$D$194,$A25,'Line Items'!$E$2:$E$194,$B25,'Line Items'!$C$2:$C$194,"<>Checking") -> 0 | E25: =C25+D25 -> 741.55
A26: Expenses | B26: paypal tiktok | C26: =SUMIFS('Line Items'!$F$2:$F$194,'Line Items'!$D$2:$D$194,$A26,'Line Items'!$E$2:$E$194,$B26,'Line Items'!$C$2:$C$194,"Checking") -> 469.52 | D26: =SUMIFS('Line Items'!$F$2:$F$194,'Line Items'!$D$2:$D$194,$A26,'Line Items'!$E$2:$E$194,$B26,'Line Items'!$C$2:$C$194,"<>Checking") -> 0 | E26: =C26+D26 -> 469.52
A27: Expenses | B27: Shop - Others | C27: =SUMIFS('Line Items'!$F$2:$F$194,'Line Items'!$D$2:$D$194,$A27,'Line Items'!$E$2:$E$194,$B27,'Line Items'!$C$2:$C$194,"Checking") -> 341.53 | D27: =SUMIFS('Line Items'!$F$2:$F$194,'Line Items'!$D$2:$D$194,$A27,'Line Items'!$E$2:$E$194,$B27,'Line Items'!$C$2:$C$194,"<>Checking") -> 53.38 | E27: =C27+D27 -> 394.91
A28: Expenses | B28: Groceries - Costco | C28: =SUMIFS('Line Items'!$F$2:$F$194,'Line Items'!$D$2:$D$194,$A28,'Line Items'!$E$2:$E$194,$B28,'Line Items'!$C$2:$C$194,"Checking") -> 0 | D28: =SUMIFS('Line Items'!$F$2:$F$194,'Line Items'!$D$2:$D$194,$A28,'Line Items'!$E$2:$E$194,$B28,'Line Items'!$C$2:$C$194,"<>Checking") -> 331 | E28: =C28+D28 -> 331
A29: Expenses | B29: Medical | C29: =SUMIFS('Line Items'!$F$2:$F$194,'Line Items'!$D$2:$D$194,$A29,'Line Items'!$E$2:$E$194,$B29,'Line Items'!$C$2:$C$194,"Checking") -> 21.66 | D29: =SUMIFS('Line Items'!$F$2:$F$194,'Line Items'!$D$2:$D$194,$A29,'Line Items'!$E$2:$E$194,$B29,'Line Items'!$C$2:$C$194,"<>Checking") -> 304.42 | E29: =C29+D29 -> 326.08
A30: Expenses | B30: Gas | C30: =SUMIFS('Line Items'!$F$2:$F$194,'Line Items'!$D$2:$D$194,$A30,'Line Items'!$E$2:$E$194,$B30,'Line Items'!$C$2:$C$194,"Checking") -> 211.4 | D30: =SUMIFS('Line Items'!$F$2:$F$194,'Line Items'!$D$2:$D$194,$A30,'Line Items'!$E$2:$E$194,$B30,'Line Items'!$C$2:$C$194,"<>Checking") -> 67.49 | E30: =C30+D30 -> 278.89
A31: Expenses | B31: Remittance - Aron | C31: =SUMIFS('Line Items'!$F$2:$F$194,'Line Items'!$D$2:$D$194,$A31,'Line Items'!$E$2:$E$194,$B31,'Line Items'!$C$2:$C$194,"Checking") -> 242.45 | D31: =SUMIFS('Line Items'!$F$2:$F$194,'Line Items'!$D$2:$D$194,$A31,'Line Items'!$E$2:$E$194,$B31,'Line Items'!$C$2:$C$194,"<>Checking") -> 0 | E31: =C31+D31 -> 242.45
A32: Expenses | B32: Food - To go | C32: =SUMIFS('Line Items'!$F$2:$F$194,'Line Items'!$D$2:$D$194,$A32,'Line Items'!$E$2:$E$194,$B32,'Line Items'!$C$2:$C$194,"Checking") -> 232.71 | D32: =SUMIFS('Line Items'!$F$2:$F$194,'Line Items'!$D$2:$D$194,$A32,'Line Items'!$E$2:$E$194,$B32,'Line Items'!$C$2:$C$194,"<>Checking") -> 0 | E32: =C32+D32 -> 232.71
A33: Expenses | B33: Groceries - Seafood City | C33: =SUMIFS('Line Items'!$F$2:$F$194,'Line Items'!$D$2:$D$194,$A33,'Line Items'!$E$2:$E$194,$B33,'Line Items'!$C$2:$C$194,"Checking") -> 175.94 | D33: =SUMIFS('Line Items'!$F$2:$F$194,'Line Items'!$D$2:$D$194,$A33,'Line Items'!$E$2:$E$194,$B33,'Line Items'!$C$2:$C$194,"<>Checking") -> 0 | E33: =C33+D33 -> 175.94
... A39: Expenses | B39: For Car | C39: =SUMIFS('Line Items'!$F$2:$F$194,'Line Items'!$D$2:$D$194,$A39,'Line Items'!$E$2:$E$194,$B39,'Line Items'!$C$2:$C$194,"Checking") -> 7 | D39: =SUMIFS('Line Items'!$F$2:$F$194,'Line Items'!$D$2:$D$194,$A39,'Line Items'!$E$2:$E$194,$B39,'Line Items'!$C$2:$C$194,"<>Checking") -> 0 | E39: =C39+D39 -> 7
A40: Total Expenses | C40: =SUM(C22:C39) -> 7566.28 | D40: =SUM(D22:D39) -> 826.29 | E40: =SUM(E22:E39) -> 8392.57
A42: Debt | B42: Affirm | C42: =SUMIFS('Line Items'!$F$2:$F$194,'Line Items'!$D$2:$D$194,$A42,'Line Items'!$E$2:$E$194,$B42,'Line Items'!$C$2:$C$194,"Checking") -> 1120.71 | D42: =SUMIFS('Line Items'!$F$2:$F$194,'Line Items'!$D$2:$D$194,$A42,'Line Items'!$E$2:$E$194,$B42,'Line Items'!$C$2:$C$194,"<>Checking") -> 0 | E42: =C42+D42 -> 1120.71
A43: Debt | B43: Auto Loan - Honda | C43: =SUMIFS('Line Items'!$F$2:$F$194,'Line Items'!$D$2:$D$194,$A43,'Line Items'!$E$2:$E$194,$B43,'Line Items'!$C$2:$C$194,"Checking") -> 709.9 | D43: =SUMIFS('Line Items'!$F$2:$F$194,'Line Items'!$D$2:$D$194,$A43,'Line Items'!$E$2:$E$194,$B43,'Line Items'!$C$2:$C$194,"<>Checking") -> 0 | E43: =C43+D43 -> 709.9
A44: Debt | B44: Auto Loan - WRX | C44: =SUMIFS('Line Items'!$F$2:$F$194,'Line Items'!$D$2:$D$194,$A44,'Line Items'!$E$2:$E$194,$B44,'Line Items'!$C$2:$C$194,"Checking") -> 706.36 | D44: =SUMIFS('Line Items'!$F$2:$F$194,'Line Items'!$D$2:$D$194,$A44,'Line Items'!$E$2:$E$194,$B44,'Line Items'!$C$2:$C$194,"<>Checking") -> 0 | E44: =C44+D44 -> 706.36
A45: Debt | B45: Auto Loan - Miata | C45: =SUMIFS('Line Items'!$F$2:$F$194,'Line Items'!$D$2:$D$194,$A45,'Line Items'!$E$2:$E$194,$B45,'Line Items'!$C$2:$C$194,"Checking") -> 500 | D45: =SUMIFS('Line Items'!$F$2:$F$194,'Line Items'!$D$2:$D$194,$A45,'Line Items'!$E$2:$E$194,$B45,'Line Items'!$C$2:$C$194,"<>Checking") -> 0 | E45: =C45+D45 -> 500
A46: Debt | B46: Klarna | C46: =SUMIFS('Line Items'!$F$2:$F$194,'Line Items'!$D$2:$D$194,$A46,'Line Items'!$E$2:$E$194,$B46,'Line Items'!$C$2:$C$194,"Checking") -> 214.19 | D46: =SUMIFS('Line Items'!$F$2:$F$194,'Line Items'!$D$2:$D$194,$A46,'Line Items'!$E$2:$E$194,$B46,'Line Items'!$C$2:$C$194,"<>Checking") -> 0 | E46: =C46+D46 -> 214.19
A47: Debt | B47: Chase Pay in 4 | C47: =SUMIFS('Line Items'!$F$2:$F$194,'Line Items'!$D$2:$D$194,$A47,'Line Items'!$E$2:$E$194,$B47,'Line Items'!$C$2:$C$194,"Checking") -> 150.4 | D47: =SUMIFS('Line Items'!$F$2:$F$194,'Line Items'!$D$2:$D$194,$A47,'Line Items'!$E$2:$E$194,$B47,'Line Items'!$C$2:$C$194,"<>Checking") -> 0 | E47: =C47+D47 -> 150.4
A48: Debt | B48: CC - Credit 1 | C48: =SUMIFS('Line Items'!$F$2:$F$194,'Line Items'!$D$2:$D$194,$A48,'Line Items'!$E$2:$E$194,$B48,'Line Items'!$C$2:$C$194,"Checking") -> 0 | D48: =SUMIFS('Line Items'!$F$2:$F$194,'Line Items'!$D$2:$D$194,$A48,'Line Items'!$E$2:$E$194,$B48,'Line Items'!$C$2:$C$194,"<>Checking") -> 46.5 | E48: =C48+D48 -> 46.5
A49: Debt | B49: CC - Ollo | C49: =SUMIFS('Line Items'!$F$2:$F$194,'Line Items'!$D$2:$D$194,$A49,'Line Items'!$E$2:$E$194,$B49,'Line Items'!$C$2:$C$194,"Checking") -> 0 | D49: =SUMIFS('Line Items'!$F$2:$F$194,'Line Items'!$D$2:$D$194,$A49,'Line Items'!$E$2:$E$194,$B49,'Line Items'!$C$2:$C$194,"<>Checking") -> 27 | E49: =C49+D49 -> 27
A50: Debt | B50: CC - Citibank | C50: =SUMIFS('Line Items'!$F$2:$F$194,'Line Items'!$D$2:$D$194,$A50,'Line Items'!$E$2:$E$194,$B50,'Line Items'!$C$2:$C$194,"Checking") -> 0 | D50: =SUMIFS('Line Items'!$F$2:$F$194,'Line Items'!$D$2:$D$194,$A50,'Line Items'!$E$2:$E$194,$B50,'Line Items'!$C$2:$C$194,"<>Checking") -> 15.9 | E50: =C50+D50 -> 15.9
...

Sheet Line Items
A1: Date | B1: Description | C1: Source | D1: Group | E1: Category | F1: Amount
A2: 2026-09-01 | B2: DD *DOORDASH CHURCHST 855-431-0459 CA 09/01 | C2: Checking | D2: Expenses | E2: Food - To go | F2: 39.41
A3: 2026-09-01 | B3: MCDONALD'S F25291 HENDERSON NV 08/31 | C3: Checking | D3: Expenses | E3: Food - Eat Out | F3: 23.59
A4: 2026-09-01 | B4: SHELL OIL 57441199007 HENDERSON NV 08/31 | C4: Checking | D4: Expenses | E4: Gas | F4: 80.45
A5: 2026-09-01 | B5: Taptap Send New York NY 09/01 | C5: Checking | D5: Expenses | E5: Remittance - Aron | F5: 80.64
A6: 2026-09-01 | B6: COSTCO WHSE #0673 HENDERSON NV | C6: Costco Anywhere Visa (Citi) (...7561) | D6: Expenses | E6: Groceries - Costco | F6: 31.99
A7: 2026-09-01 | B7: COSTCO WHSE #0673 HENDERSON NV | C7: Costco Anywhere Visa (Citi) (...7561) | D7: Expenses | E7: Groceries - Costco | F7: 299.01
A8: 2026-09-02 | B8: AMAZON MARKETPLA INTERNET 043000097642586 WEB ID: 9049016352 | C8: Checking | D8: Expenses | E8: Shop - Amazon | F8: 9.74
A9: 2026-09-02 | B9: ATM WITHDRAWAL 000996 09/02705 S GRE | C9: Checking | D9: Expenses | E9: Others | F9: 680
A10: 2026-09-02 | B10: CHOPSTIX HENDERSON NV 09/01 | C10: Checking | D10: Expenses | E10: Others | F10: 46.22
A11: 2026-09-02 | B11: EXPRESS SMOG- HENDERSON HENDERSON NV 09/01 | C11: Checking | D11: Expenses | E11: Others | F11: 69
A12: 2026-09-02 | B12: SP+AFF * HOWLER BIKE 855-423-3729 CA 09/02 | C12: Checking | D12: Expenses | E12: For Bike | F12: 47.93
A13: 2026-09-02 | B13: TST*CASA DE EMPANADA - Las Vegas NV 09/01 | C13: Checking | D13: Expenses | E13: Food - Eat Out | F13: 74.73
... A194: 2026-09-30 | B194: zelle - mattress | C194: Checking | D194: Expenses | E194: Others | F194: 125
E195: Total | F195: =SUM(F2:F194) -> 14044.43
A197: Amounts are money spent (positive); refunds and credits are negative. Card rows are purchases, fees and interest from card statements; checking payments to those cards are left out so nothing is counted twice.
